<?xml version="1.0" encoding="UTF-8"?>
<!-- Generated by org.testng.reporters.JUnitReportReporter -->
<testsuite hostname="PC-75" failures="1" tests="2" name="KycPageTC.KYCPage" time="44.304" errors="0" timestamp="2023-10-04T19:26:35 IST" skipped="0">
  <testcase classname="KycPageTC.KYCPage" name="test2" time="4.824">
    <failure message="The following asserts failed:
	expected [s2] but found [s1]" type="java.lang.AssertionError">
      <![CDATA[java.lang.AssertionError: The following asserts failed:
expected [s2] but found [s1]
at org.testng.asserts.SoftAssert.assertAll(SoftAssert.java:46)
at org.testng.asserts.SoftAssert.assertAll(SoftAssert.java:30)
at KycPageTC.KYCPage.test2(KYCPage.java:474)
at java.base/jdk.internal.reflect.NativeMethodAccessorImpl.invoke0(Native Method)
at java.base/jdk.internal.reflect.NativeMethodAccessorImpl.invoke(NativeMethodAccessorImpl.java:77)
at java.base/jdk.internal.reflect.DelegatingMethodAccessorImpl.invoke(DelegatingMethodAccessorImpl.java:43)
at java.base/java.lang.reflect.Method.invoke(Method.java:568)
at org.testng.internal.invokers.MethodInvocationHelper.invokeMethod(MethodInvocationHelper.java:139)
at org.testng.internal.invokers.InvokeMethodRunnable.runOne(InvokeMethodRunnable.java:47)
at org.testng.internal.invokers.InvokeMethodRunnable.call(InvokeMethodRunnable.java:76)
at org.testng.internal.invokers.InvokeMethodRunnable.call(InvokeMethodRunnable.java:11)
at java.base/java.util.concurrent.FutureTask.run(FutureTask.java:264)
at java.base/java.util.concurrent.ThreadPoolExecutor.runWorker(ThreadPoolExecutor.java:1136)
at java.base/java.util.concurrent.ThreadPoolExecutor$Worker.run(ThreadPoolExecutor.java:635)
at java.base/java.lang.Thread.run(Thread.java:833)
]]>
    </failure>
  </testcase> <!-- test2 -->
  <testcase classname="KycPageTC.KYCPage" name="KYCFormFill" time="39.480">
    <system-out>
      <![CDATA[true]]>
    </system-out>
  </testcase> <!-- KYCFormFill -->
  <system-out>
    <![CDATA[true]]>
  </system-out>
</testsuite> <!-- KycPageTC.KYCPage -->
